package main

import (
	"fmt"
	"os"
	"testing"
)

func TestMain(t *testing.T) {
	// Test that main function doesn't panic
	// We can't easily test the actual execution without mocking cmd.Execute
	// but we can test that the function exists and is callable

	// Save original args and restore after test
	originalArgs := os.Args
	defer func() {
		os.Args = originalArgs
	}()

	// Set test args to avoid actual command execution
	os.Args = []string{"gitpersona", "--help"}

	// Test that main function can be called without panicking
	// Note: This will actually execute the help command, but that's safe
	defer func() {
		if r := recover(); r != nil {
			t.Errorf("main() panicked: %v", r)
		}
	}()

	// We can't directly call main() in a test, but we can test the logic
	// by testing the error handling path
	t.Run("error_handling", func(t *testing.T) {
		// Test error handling logic (simulated)
		err := fmt.Errorf("test error")
		if err != nil {
			// This simulates the error handling in main()
			// We can't easily test the actual os.Exit(1) call
			if err.Error() != "test error" {
				t.Errorf("Expected 'test error', got '%s'", err.Error())
			}
		}
	})
}

// TestMainFunctionExists tests that the main function exists and is accessible
func TestMainFunctionExists(t *testing.T) {
	// This test ensures the main function is properly defined
	// We can't call it directly, but we can verify it exists through reflection
	// or by ensuring the package compiles correctly

	// If we reach this point, the main function exists and the package compiles
	t.Log("main function exists and package compiles successfully")
}
